 
Traceback (most recent call last):
  File "/home/retupmoc/PycharmProjects/boundFetch/boundFetch.py", line 16, in <module>
    driver = webdriver.Firefox(service=service, options=options)
             ^^^^^^^^^^^^^^^^^^^^^^^^^^^^^^^^^^^^^^^^^^^^^^^^^^^
  File "/home/retupmoc/PycharmProjects/boundFetch/venv/lib/python3.11/site-packages/selenium/webdriver/firefox/webdriver.py", line 67, in __init__
    super().__init__(command_executor=executor, options=options)
  File "/home/retupmoc/PycharmProjects/boundFetch/venv/lib/python3.11/site-packages/selenium/webdriver/remote/webdriver.py", line 208, in __init__
    self.start_session(capabilities)
  File "/home/retupmoc/PycharmProjects/boundFetch/venv/lib/python3.11/site-packages/selenium/webdriver/remote/webdriver.py", line 292, in start_session
    response = self.execute(Command.NEW_SESSION, caps)["value"]
               ^^^^^^^^^^^^^^^^^^^^^^^^^^^^^^^^^^^^^^^
  File "/home/retupmoc/PycharmProjects/boundFetch/venv/lib/python3.11/site-packages/selenium/webdriver/remote/webdriver.py", line 347, in execute
    self.error_handler.check_response(response)
  File "/home/retupmoc/PycharmProjects/boundFetch/venv/lib/python3.11/site-packages/selenium/webdriver/remote/errorhandler.py", line 229, in check_response
    raise exception_class(message, screen, stacktrace)
selenium.common.exceptions.WebDriverException: Message: Process unexpectedly closed with status 1

Traceback (most recent call last):
  File "/home/retupmoc/PycharmProjects/boundFetch/boundFetch.py", line 16, in <module>
    driver = webdriver.Firefox(service=service, options=options)
             ^^^^^^^^^^^^^^^^^^^^^^^^^^^^^^^^^^^^^^^^^^^^^^^^^^^
  File "/home/retupmoc/PycharmProjects/boundFetch/venv/lib/python3.11/site-packages/selenium/webdriver/firefox/webdriver.py", line 67, in __init__
    super().__init__(command_executor=executor, options=options)
  File "/home/retupmoc/PycharmProjects/boundFetch/venv/lib/python3.11/site-packages/selenium/webdriver/remote/webdriver.py", line 208, in __init__
    self.start_session(capabilities)
  File "/home/retupmoc/PycharmProjects/boundFetch/venv/lib/python3.11/site-packages/selenium/webdriver/remote/webdriver.py", line 292, in start_session
    response = self.execute(Command.NEW_SESSION, caps)["value"]
               ^^^^^^^^^^^^^^^^^^^^^^^^^^^^^^^^^^^^^^^
  File "/home/retupmoc/PycharmProjects/boundFetch/venv/lib/python3.11/site-packages/selenium/webdriver/remote/webdriver.py", line 347, in execute
    self.error_handler.check_response(response)
  File "/home/retupmoc/PycharmProjects/boundFetch/venv/lib/python3.11/site-packages/selenium/webdriver/remote/errorhandler.py", line 229, in check_response
    raise exception_class(message, screen, stacktrace)
selenium.common.exceptions.WebDriverException: Message: Process unexpectedly closed with status 1

Traceback (most recent call last):
  File "/home/retupmoc/PycharmProjects/boundFetch/boundFetch.py", line 30, in <module>
    header_to_sort.click()
  File "/home/retupmoc/PycharmProjects/boundFetch/venv/lib/python3.11/site-packages/selenium/webdriver/remote/webelement.py", line 93, in click
    self._execute(Command.CLICK_ELEMENT)
  File "/home/retupmoc/PycharmProjects/boundFetch/venv/lib/python3.11/site-packages/selenium/webdriver/remote/webelement.py", line 394, in _execute
    return self._parent.execute(command, params)
           ^^^^^^^^^^^^^^^^^^^^^^^^^^^^^^^^^^^^^
  File "/home/retupmoc/PycharmProjects/boundFetch/venv/lib/python3.11/site-packages/selenium/webdriver/remote/webdriver.py", line 347, in execute
    self.error_handler.check_response(response)
  File "/home/retupmoc/PycharmProjects/boundFetch/venv/lib/python3.11/site-packages/selenium/webdriver/remote/errorhandler.py", line 229, in check_response
    raise exception_class(message, screen, stacktrace)
selenium.common.exceptions.ElementClickInterceptedException: Message: Element <th> is not clickable at point (491,604) because another element <div id="onetrust-policy-text"> obscures it
Stacktrace:
RemoteError@chrome://remote/content/shared/RemoteError.sys.mjs:8:8
WebDriverError@chrome://remote/content/shared/webdriver/Errors.sys.mjs:189:5
ElementClickInterceptedError@chrome://remote/content/shared/webdriver/Errors.sys.mjs:333:5
webdriverClickElement@chrome://remote/content/marionette/interaction.sys.mjs:176:11
interaction.clickElement@chrome://remote/content/marionette/interaction.sys.mjs:135:11
clickElement@chrome://remote/content/marionette/actors/MarionetteCommandsChild.sys.mjs:202:29
receiveMessage@chrome://remote/content/marionette/actors/MarionetteCommandsChild.sys.mjs:84:31

There was an error managing firefox (error sending request for url (https://github.com/mozilla/geckodriver/releases/latest): error trying to connect: dns error: failed to lookup address information: Try again); using driver found in the cache
Traceback (most recent call last):
  File "/home/retupmoc/PycharmProjects/boundFetch/boundFetch.py", line 16, in <module>
    driver = webdriver.Firefox(service=service, options=options)
             ^^^^^^^^^^^^^^^^^^^^^^^^^^^^^^^^^^^^^^^^^^^^^^^^^^^
  File "/home/retupmoc/PycharmProjects/boundFetch/venv/lib/python3.11/site-packages/selenium/webdriver/firefox/webdriver.py", line 67, in __init__
    super().__init__(command_executor=executor, options=options)
  File "/home/retupmoc/PycharmProjects/boundFetch/venv/lib/python3.11/site-packages/selenium/webdriver/remote/webdriver.py", line 208, in __init__
    self.start_session(capabilities)
  File "/home/retupmoc/PycharmProjects/boundFetch/venv/lib/python3.11/site-packages/selenium/webdriver/remote/webdriver.py", line 292, in start_session
    response = self.execute(Command.NEW_SESSION, caps)["value"]
               ^^^^^^^^^^^^^^^^^^^^^^^^^^^^^^^^^^^^^^^
  File "/home/retupmoc/PycharmProjects/boundFetch/venv/lib/python3.11/site-packages/selenium/webdriver/remote/webdriver.py", line 347, in execute
    self.error_handler.check_response(response)
  File "/home/retupmoc/PycharmProjects/boundFetch/venv/lib/python3.11/site-packages/selenium/webdriver/remote/errorhandler.py", line 229, in check_response
    raise exception_class(message, screen, stacktrace)
selenium.common.exceptions.WebDriverException: Message: Invalid Host header localhost:55417

Traceback (most recent call last):
  File "/home/retupmoc/PycharmProjects/boundFetch/boundFetch.py", line 19, in <module>
    driver = webdriver.Firefox(service=service, options=options)
             ^^^^^^^^^^^^^^^^^^^^^^^^^^^^^^^^^^^^^^^^^^^^^^^^^^^
  File "/home/retupmoc/PycharmProjects/boundFetch/venv/lib/python3.11/site-packages/selenium/webdriver/firefox/webdriver.py", line 67, in __init__
    super().__init__(command_executor=executor, options=options)
  File "/home/retupmoc/PycharmProjects/boundFetch/venv/lib/python3.11/site-packages/selenium/webdriver/remote/webdriver.py", line 208, in __init__
    self.start_session(capabilities)
  File "/home/retupmoc/PycharmProjects/boundFetch/venv/lib/python3.11/site-packages/selenium/webdriver/remote/webdriver.py", line 292, in start_session
    response = self.execute(Command.NEW_SESSION, caps)["value"]
               ^^^^^^^^^^^^^^^^^^^^^^^^^^^^^^^^^^^^^^^
  File "/home/retupmoc/PycharmProjects/boundFetch/venv/lib/python3.11/site-packages/selenium/webdriver/remote/webdriver.py", line 347, in execute
    self.error_handler.check_response(response)
  File "/home/retupmoc/PycharmProjects/boundFetch/venv/lib/python3.11/site-packages/selenium/webdriver/remote/errorhandler.py", line 229, in check_response
    raise exception_class(message, screen, stacktrace)
selenium.common.exceptions.WebDriverException: Message: Invalid Host header localhost:35327

  File "/home/retupmoc/PycharmProjects/boundFetch/boundFetch.py", line 1
    import csv
IndentationError: unexpected indent
  File "/home/retupmoc/PycharmProjects/boundFetch/boundFetch.py", line 1
    import csv
IndentationError: unexpected indent
There was an error managing firefox (error sending request for url (https://github.com/mozilla/geckodriver/releases/latest): error trying to connect: dns error: failed to lookup address information: Try again); using driver found in the cache
Traceback (most recent call last):
  File "/home/retupmoc/PycharmProjects/boundFetch/boundFetch.py", line 19, in <module>
    driver = webdriver.Firefox(service=service, options=options)
             ^^^^^^^^^^^^^^^^^^^^^^^^^^^^^^^^^^^^^^^^^^^^^^^^^^^
  File "/home/retupmoc/PycharmProjects/boundFetch/venv/lib/python3.11/site-packages/selenium/webdriver/firefox/webdriver.py", line 67, in __init__
    super().__init__(command_executor=executor, options=options)
  File "/home/retupmoc/PycharmProjects/boundFetch/venv/lib/python3.11/site-packages/selenium/webdriver/remote/webdriver.py", line 208, in __init__
    self.start_session(capabilities)
  File "/home/retupmoc/PycharmProjects/boundFetch/venv/lib/python3.11/site-packages/selenium/webdriver/remote/webdriver.py", line 292, in start_session
    response = self.execute(Command.NEW_SESSION, caps)["value"]
               ^^^^^^^^^^^^^^^^^^^^^^^^^^^^^^^^^^^^^^^
  File "/home/retupmoc/PycharmProjects/boundFetch/venv/lib/python3.11/site-packages/selenium/webdriver/remote/webdriver.py", line 347, in execute
    self.error_handler.check_response(response)
  File "/home/retupmoc/PycharmProjects/boundFetch/venv/lib/python3.11/site-packages/selenium/webdriver/remote/errorhandler.py", line 229, in check_response
    raise exception_class(message, screen, stacktrace)
selenium.common.exceptions.WebDriverException: Message: Invalid Host header localhost:52637

Traceback (most recent call last):
  File "/home/retupmoc/PycharmProjects/boundFetch/boundFetch.py", line 19, in <module>
    driver = webdriver.Firefox(service=service, options=options)
             ^^^^^^^^^^^^^^^^^^^^^^^^^^^^^^^^^^^^^^^^^^^^^^^^^^^
  File "/home/retupmoc/PycharmProjects/boundFetch/venv/lib/python3.11/site-packages/selenium/webdriver/firefox/webdriver.py", line 67, in __init__
    super().__init__(command_executor=executor, options=options)
  File "/home/retupmoc/PycharmProjects/boundFetch/venv/lib/python3.11/site-packages/selenium/webdriver/remote/webdriver.py", line 208, in __init__
    self.start_session(capabilities)
  File "/home/retupmoc/PycharmProjects/boundFetch/venv/lib/python3.11/site-packages/selenium/webdriver/remote/webdriver.py", line 292, in start_session
    response = self.execute(Command.NEW_SESSION, caps)["value"]
               ^^^^^^^^^^^^^^^^^^^^^^^^^^^^^^^^^^^^^^^
  File "/home/retupmoc/PycharmProjects/boundFetch/venv/lib/python3.11/site-packages/selenium/webdriver/remote/webdriver.py", line 347, in execute
    self.error_handler.check_response(response)
  File "/home/retupmoc/PycharmProjects/boundFetch/venv/lib/python3.11/site-packages/selenium/webdriver/remote/errorhandler.py", line 229, in check_response
    raise exception_class(message, screen, stacktrace)
selenium.common.exceptions.WebDriverException: Message: Invalid Host header localhost:35635

Traceback (most recent call last):
  File "/home/retupmoc/PycharmProjects/boundFetch/boundFetch.py", line 20, in <module>
    driver = webdriver.Firefox(service=service, options=options)
             ^^^^^^^^^^^^^^^^^^^^^^^^^^^^^^^^^^^^^^^^^^^^^^^^^^^
  File "/home/retupmoc/PycharmProjects/boundFetch/venv/lib/python3.11/site-packages/selenium/webdriver/firefox/webdriver.py", line 67, in __init__
    super().__init__(command_executor=executor, options=options)
  File "/home/retupmoc/PycharmProjects/boundFetch/venv/lib/python3.11/site-packages/selenium/webdriver/remote/webdriver.py", line 208, in __init__
    self.start_session(capabilities)
  File "/home/retupmoc/PycharmProjects/boundFetch/venv/lib/python3.11/site-packages/selenium/webdriver/remote/webdriver.py", line 292, in start_session
    response = self.execute(Command.NEW_SESSION, caps)["value"]
               ^^^^^^^^^^^^^^^^^^^^^^^^^^^^^^^^^^^^^^^
  File "/home/retupmoc/PycharmProjects/boundFetch/venv/lib/python3.11/site-packages/selenium/webdriver/remote/webdriver.py", line 347, in execute
    self.error_handler.check_response(response)
  File "/home/retupmoc/PycharmProjects/boundFetch/venv/lib/python3.11/site-packages/selenium/webdriver/remote/errorhandler.py", line 229, in check_response
    raise exception_class(message, screen, stacktrace)
selenium.common.exceptions.WebDriverException: Message: Invalid Host header localhost:43117

There was an error managing firefox (error sending request for url (https://github.com/mozilla/geckodriver/releases/latest): error trying to connect: dns error: failed to lookup address information: Try again); using driver found in the cache
Traceback (most recent call last):
  File "/home/retupmoc/PycharmProjects/boundFetch/boundFetch.py", line 20, in <module>
    driver = webdriver.Firefox(service=service, options=options)
             ^^^^^^^^^^^^^^^^^^^^^^^^^^^^^^^^^^^^^^^^^^^^^^^^^^^
  File "/home/retupmoc/PycharmProjects/boundFetch/venv/lib/python3.11/site-packages/selenium/webdriver/firefox/webdriver.py", line 67, in __init__
    super().__init__(command_executor=executor, options=options)
  File "/home/retupmoc/PycharmProjects/boundFetch/venv/lib/python3.11/site-packages/selenium/webdriver/remote/webdriver.py", line 208, in __init__
    self.start_session(capabilities)
  File "/home/retupmoc/PycharmProjects/boundFetch/venv/lib/python3.11/site-packages/selenium/webdriver/remote/webdriver.py", line 292, in start_session
    response = self.execute(Command.NEW_SESSION, caps)["value"]
               ^^^^^^^^^^^^^^^^^^^^^^^^^^^^^^^^^^^^^^^
  File "/home/retupmoc/PycharmProjects/boundFetch/venv/lib/python3.11/site-packages/selenium/webdriver/remote/webdriver.py", line 347, in execute
    self.error_handler.check_response(response)
  File "/home/retupmoc/PycharmProjects/boundFetch/venv/lib/python3.11/site-packages/selenium/webdriver/remote/errorhandler.py", line 229, in check_response
    raise exception_class(message, screen, stacktrace)
selenium.common.exceptions.WebDriverException: Message: Invalid Host header localhost:47467

